Workbook

Sheet Intro
A1: Watershed Area of Suitable Habitat (WASH) Systems Model
A3: Developed by:
A4: Ayman H. Alafifi
A5: Dept. of Civil & Env. Engineering and Utah Water Research Lab Utah State University ayman.alafifi@gmail.com
A7: Version 1.0
A8: Updated: | B8: March 9,2016 | C8: Today: | D8: =NOW() -> 45960.944
A9: Copyright and licenses: | C9: Click here
A11: Introduction
A12: WASH is a system optimization model that maximized water allocation to environmental needs while maintaining human and other beneficial uses. WASH receommends allocation of water to improve habitat quality by incorporating habitat quality indexes as objectives to maximize in a systems optimization model. WASH measures physically-available suitable habitat in three main components of most watersheds, namely riverine, floodplain and wetland habitats. WASH also highlights promising restoration and conservation sites. In addition, WASH considers, quantifies, and measures multiple sources of uncertainty in management decisions and proposes and rank alternatives for managers to restore and protect natural habitat. WASH formulation is generic and adaptable to other regulated river systems and can accomodate multiple priority species of concern. The code below desrcibes the WASH optimization model and includes the objecttive function, decision variables and constraints in addition to all the parameters that are required to run the model. The model reads all the parameters as input data from Excel and writes the results to an Excel file for fuether processing.
A25: Citation:
A28: Code on GitHub:
A29: https://github.com/ayman510/WASH
A31: Instructions:
A32: This workbook provides the input data for the WASH model. The model reads this input data into a GDX file and then load the GDX content to the model as parameters. All values of this input data is for the case of the Lower Bear River in Utah.
A33: The full network for which the data here are dervied can be found here: | F33: Lower Bear River Network
A34: To change any input value:
A35: 1. Use table (1) below for find the input parameter that you want to edit
A36: 2. Click on the hyperlink to go directly to the parameter's sheet
A37: 3. Do NOT change the index cells unless you want to change the domain of the input value
A38: 4. Edit the values of the parameters and then SAVE THE WORKBOOK
A39: 5. Run the GAMS model to see changes in the model results
A42: Table (1) Input data and parameters for the WASH model
A43: Type | B43: Name | C43: Description
A44: Set | B44: s | C44: sub-indicators. Here s1=riverine habitat s2=floodplain connectivity and s3=impounded wetlands
A45: Set | B45: j | C45: river netowrk nodes which lists all nodes in the network
A46: Set | B46: dem | C46: demand sites which are a subset of the model nodes (j)
A47: Set | B47: v | C47: reservoirs which are a subset of the model nodes (j)
A48: Set | B48: y | C48: The type(s) of priorty fish species that the model uses as indicator species
A49: Set | B49: n | C49: The type(s) of prioty vegetation species that the model uses as indicator species
A50: Set | B50: t | C50: timesteps in months (t1 =January - t12=December)
A51: Set | B51: RA_par_indx | C51: indexes to read the parameters for the reservoir volume elevation curves
A52: Set | B52: sf_par_indx | C52: indexes to read the parameters for stage-flow relationships
A53: Set | B53: wf_par_indx | C53: indexes to read the parameters for width-flow relationships
A54: Set | B54: wsi_par_indx | C54: indexes to read the parameters for wetlands suitability index relationships
... A95: Scalar | B95: b | C95: Total management budget to implement restoration actions [$]

Sheet Copyright & License
A1: Copyright (c) 2016, Ayman H. Alafifi and David E. Rosenberg
A2: All rights reserved.
A3: Redistribution and use in source and binary forms, with or without modification, are permitted provided that the following conditions are met: 1. Redistributions of source code must retain the above copyright notice, this list of conditions and the following disclaimer. 2. Redistributions in binary form must reproduce the above copyright notice, this list of conditions and the following disclaimer in the documentation and/or other materials provided with the distribution. 3. Neither the name of the copyright holder nor the names of its contributors may be used to endorse or promote products derived from this software without specific prior written permission. THIS SOFTWARE IS PROVIDED BY THE COPYRIGHT HOLDERS AND CONTRIBUTORS "AS IS" AND ANY EXPRESS OR IMPLIED WARRANTIES, INCLUDING, BUT NOT LIMITED TO, THE IMPLIED WARRANTIES OF MERCHANTABILITY AND FITNESS FOR A PARTICULAR PURPOSE ARE DISCLAIMED. IN NO EVENT SHALL THE COPYRIGHT HOLDER OR CONTRIBUTORS BE LIABLE FOR ANY DIRECT, INDIRECT, INCIDENTAL, SPECIAL, EXEMPLARY, OR CONSEQUENTIAL DAMAGES (INCLUDING, BUT NOT LIMITED TO, PROCUREMENT OF SUBSTITUTE GOODS OR SERVICES; LOSS OF USE, DATA, OR PROFITS; OR BUSINESS INTERRUPTION) HOWEVER CAUSED AND ON ANY THEORY OF LIABILITY, WHETHER IN CONTRACT, STRICT LIABILITY, OR TORT (INCLUDING NEGLIGENCE OR OTHERWISE) ARISING IN ANY WAY OUT OF THE USE OF THIS SOFTWARE, EVEN IF ADVISED OF THE POSSIBILITY OF SUCH DAMAGE.

Sheet BearRiverNetwork
D2: The Lower Bear River Network | P2: The Lower Bear River Map

Sheet SubInd
A1: riverine
A2: floodplain
A3: wetlands

Sheet FishSpp
A1: trout

Sheet VegSpp
A1: cottonwood

Sheet Month
A1: t1
A2: t2
A3: t3
A4: t4
A5: t5
A6: t6
A7: t7
A8: t8
A9: t9
A10: t10
A11: t11
A12: t12

Sheet Nodes
A1: j1
A2: j2
A3: j3
A4: j4
A5: j5
A6: j6
A7: j7
A8: j8
A9: j9
A10: j12
A11: j13
A12: j14
... A43: j45

Sheet NodesNotDemand
A1: j1
A2: j2
A3: j4
A4: j5
A5: j6
A6: j7
A7: j9
A8: j12
A9: j14
A10: j17
A11: j18
A12: j19
... A31: j45

Sheet NodeNotHeadwater
A1: j1
A2: j3
A3: j4
A4: j5
A5: j8
A6: j9
A7: j12
A8: j13
A9: j14
A10: j15
A11: j16
A12: j17
... A33: j45

Sheet MassBalanceNodes
A1: j4
A2: j5
A3: j6
A4: j9
A5: j12
A6: j14
A7: j18
A8: j19
A9: j20
A10: j21
A11: j22
A12: j23
... A25: j45

Sheet Reservoirs
A1: j1
A2: j7
A3: j17
A4: j29
A5: j33

Sheet Wetlands
A1: j23

Sheet Demand
A1: j3
A2: j39
A3: j8
A4: j13
A5: j15
A6: j16
A7: j27
A8: j28
A9: j38
A10: j41
A11: j42
A12: j44

Sheet R_indx
A1: RA_par1
A2: RA_par2
A3: RA_par3

Sheet sf_indx
A1: sf_par1
A2: sf_par2

Sheet wf_indx
A1: wf_par1
A2: wf_par2

Sheet wsi_indx
A1: wsi_par1
A2: wsi_par2

Sheet Connect
B1: j1 | C1: j2 | D1: j3 | E1: j4 | F1: j5 | G1: j6 | H1: j7 | I1: j8 | J1: j9 | K1: j12 | L1: j13 | M1: j14 | N1: j15 | O1: j16 | P1: j17 | Q1: j18 | R1: j19 | S1: j20 | T1: j21 | U1: j22 | V1: j23 | W1: j24 | X1: j25 | Y1: j26 | Z1: j27 | AA1: j28 | AB1: j29 | AC1: j30 | AD1: j31 | AE1: j32 | AF1: j33 | AG1: j34 | AH1: j35 | AI1: j36 | AJ1: j37 | AK1: j38 | AL1: j39 | AM1: j40 | AN1: j41 | AO1: j42 | AP1: j43 | AQ1: j44 | AR1: j45
A2: j1 | E2: 1
A3: j2 | D3: 1
A4: j3 | Q4: 1
A5: j4 | D5: 1 | F5: 1 | AL5: 1
A6: j5 | Q6: 1
A7: j6 | F7: 1
A8: j7 | I8: 1 | J8: 1 | O8: 1
A9: j8 | J9: 1
A10: j9 | K10: 1
A11: j12 | L11: 1 | M11: 1 | N11: 1
A12: j13 | M12: 1
A13: j14 | P13: 1
A14: j15 | M14: 1
A15: j16
A16: j17 | O16: 1 | S16: 1
A17: j18 | H17: 1
A18: j19 | S18: 1
A19: j20 | T19: 1
A20: j21 | V20: 1
A21: j22 | S21: 1
A22: j23
A23: j24 | H23: 1
A24: j25 | W24: 1
A25: j26 | X25: 1
A26: j27 | X26: 1
A27: j28 | W27: 1
A28: j29 | W28: 1 | Z28: 1 | AA28: 1 | AQ28: 1
A29: j30 | X29: 1 | Z29: 1
A30: j31 | AC30: 1
A31: j32 | AB31: 1
A32: j33 | AK32: 1 | AP32: 1
A33: j34 | AF33: 1
A34: j35 | AM34: 1
A35: j36 | H35: 1
A36: j37 | B36: 1
A37: j38 | AC37: 1
A38: j39 | Q38: 1
A39: j40 | AE39: 1 | AR39: 1
A40: j41 | AB40: 1
...

Sheet EnvSite
B1: j1 | C1: j2 | D1: j3 | E1: j4 | F1: j5 | G1: j6 | H1: j7 | I1: j8 | J1: j9 | K1: j10 | L1: j11 | M1: j12 | N1: j13 | O1: j14 | P1: j15 | Q1: j16 | R1: j17 | S1: j18 | T1: j19 | U1: j20 | V1: j21 | W1: j22 | X1: j23 | Y1: j24 | Z1: j25 | AA1: j26 | AB1: j27 | AC1: j28 | AD1: j29 | AE1: j30 | AF1: j31 | AG1: j32 | AH1: j33 | AI1: j34 | AJ1: j35 | AK1: j36 | AL1: j37 | AM1: j38 | AN1: j39 | AO1: j40 | AP1: j41 | AQ1: j42 | AR1: j43 | AS1: j44 | AT1: j45
A2: j1 | E2: 1
A3: j2
A4: j3
A5: j4 | F5: 1
A6: j5 | S6: 1
A7: j6 | F7: 1
A8: j7 | J8: 1
A9: j8
A10: j9 | M10: 1
A11: j10
A12: j11
A13: j12 | O13: 1
A14: j13
A15: j14 | R15: 1
A16: j15
A17: j16
A18: j17 | U18: 1
A19: j18 | H19: 1
A20: j19 | U20: 1
A21: j20 | V21: 1
A22: j21 | X22: 1
A23: j22
A24: j23
A25: j24 | H25: 1
A26: j25 | Y26: 1
A27: j26
A28: j27
A29: j28
A30: j29 | Y30: 1
A31: j30 | Z31: 1
A32: j31 | AE32: 1
A33: j32 | AD33: 1
A34: j33 | AR34: 1
A35: j34 | AH35: 1
A36: j35 | AO36: 1
A37: j36
A38: j37 | B38: 1
A39: j38
A40: j39
...

Sheet Diversions
B1: j1 | C1: j2 | D1: j3 | E1: j4 | F1: j5 | G1: j6 | H1: j7 | I1: j8 | J1: j9 | K1: j12 | L1: j13 | M1: j14 | N1: j15 | O1: j16 | P1: j17 | Q1: j18 | R1: j19 | S1: j20 | T1: j21 | U1: j22 | V1: j23 | W1: j24 | X1: j25 | Y1: j26 | Z1: j27 | AA1: j28 | AB1: j29 | AC1: j30 | AD1: j31 | AE1: j32 | AF1: j33 | AG1: j34 | AH1: j35 | AI1: j36 | AJ1: j37 | AK1: j38 | AL1: j39 | AM1: j40 | AN1: j41 | AO1: j42 | AP1: j43 | AQ1: j44 | AR1: j45
A2: j1
A3: j2 | D3: 1
A4: j3
A5: j4 | D5: 1 | AL5: 1
A6: j5
A7: j6
A8: j7 | I8: 1 | O8: 1
A9: j8
A10: j9
A11: j12 | L11: 1 | N11: 1
A12: j13
A13: j14
A14: j15
A15: j16
A16: j17 | O16: 1
A17: j18
A18: j19
A19: j20
A20: j21
A21: j22
A22: j23
A23: j24
A24: j25
A25: j26
A26: j27
A27: j28
A28: j29 | Z28: 1 | AA28: 1 | AQ28: 1
A29: j30 | Z29: 1
A30: j31
A31: j32
A32: j33 | AK32: 1
A33: j34
A34: j35
A35: j36
A36: j37
A37: j38
A38: j39
A39: j40
A40: j41
...

Sheet ReturnFlow
B1: j1 | C1: j2 | D1: j3 | E1: j4 | F1: j5 | G1: j6 | H1: j7 | I1: j8 | J1: j9 | K1: j12 | L1: j13 | M1: j14 | N1: j15 | O1: j16 | P1: j17 | Q1: j18 | R1: j19 | S1: j20 | T1: j21 | U1: j22 | V1: j23 | W1: j24 | X1: j25 | Y1: j26 | Z1: j27 | AA1: j28 | AB1: j29 | AC1: j30 | AD1: j31 | AE1: j32 | AF1: j33 | AG1: j34 | AH1: j35 | AI1: j36 | AJ1: j37 | AK1: j38 | AL1: j39 | AM1: j40 | AN1: j41 | AO1: j42 | AP1: j43 | AQ1: j44 | AR1: j45
A2: j1
A3: j2
A4: j3 | Q4: 1
A5: j4
A6: j5
A7: j6
A8: j7
A9: j8 | J9: 1
A10: j9
A11: j12
A12: j13 | M12: 1
A13: j14
A14: j15 | M14: 1
A15: j16
A16: j17
A17: j18
A18: j19
A19: j20
A20: j21
A21: j22
A22: j23
A23: j24
A24: j25
A25: j26
A26: j27 | X26: 1
A27: j28 | W27: 1
A28: j29
A29: j30
A30: j31
A31: j32
A32: j33
A33: j34
A34: j35
A35: j36
A36: j37
A37: j38 | AC37: 1
A38: j39 | Q38: 1
A39: j40
A40: j41 | AB40: 1
...

Sheet WetlandsSites
B1: j1 | C1: j2 | D1: j3 | E1: j4 | F1: j5 | G1: j6 | H1: j7 | I1: j8 | J1: j9 | K1: j10 | L1: j11 | M1: j12 | N1: j13 | O1: j14 | P1: j15 | Q1: j16 | R1: j17 | S1: j18 | T1: j19 | U1: j20 | V1: j21 | W1: j22 | X1: j23 | Y1: j24 | Z1: j25 | AA1: j26 | AB1: j27 | AC1: j28 | AD1: j29 | AE1: j30 | AF1: j31 | AG1: j32 | AH1: j33 | AI1: j34 | AJ1: j35 | AK1: j36 | AL1: j37 | AM1: j38 | AN1: j39 | AO1: j40 | AP1: j41 | AQ1: j42 | AR1: j43 | AS1: j44 | AT1: j45
A2: j1
A3: j2
A4: j3
A5: j4
A6: j5
A7: j6
A8: j7
A9: j8
A10: j9
A11: j10
A12: j11
A13: j12
... A21: j20
A22: j21 | X22: 1
A23: j22
A24: j23
A25: j24
A26: j25
A27: j26
A28: j27
A29: j28
A30: j29
A31: j30
A32: j31
A33: j32
A34: j33
... A46: j45

Sheet LinktoReservoir
B1: j1 | C1: j2 | D1: j3 | E1: j4 | F1: j5 | G1: j6 | H1: j7 | I1: j8 | J1: j9 | K1: j12 | L1: j13 | M1: j14 | N1: j15 | O1: j16 | P1: j17 | Q1: j18 | R1: j19 | S1: j20 | T1: j21 | U1: j22 | V1: j23 | W1: j24 | X1: j25 | Y1: j26 | Z1: j27 | AA1: j28 | AB1: j29 | AC1: j30 | AD1: j31 | AE1: j32 | AF1: j33 | AG1: j34 | AH1: j35 | AI1: j36 | AJ1: j37 | AK1: j38 | AL1: j39 | AM1: j40 | AN1: j41 | AO1: j42 | AP1: j43 | AQ1: j44 | AR1: j45
A2: j1
A3: j2
A4: j3
A5: j4
A6: j5
A7: j6
A8: j7
A9: j8
A10: j9
A11: j12
A12: j13
A13: j14 | P13: 1
A14: j15
A15: j16
A16: j17
A17: j18 | H17: 1
A18: j19
A19: j20
A20: j21
A21: j22
A22: j23
A23: j24 | H23: 1
A24: j25
A25: j26
A26: j27
A27: j28
A28: j29
A29: j30
A30: j31
A31: j32 | AB31: 1
A32: j33
A33: j34 | AF33: 1
A34: j35
A35: j36 | H35: 1
A36: j37 | B36: 1
A37: j38
A38: j39
A39: j40
A40: j41 | AB40: 1
...

Sheet LinkOutReservoir
B1: j1 | C1: j2 | D1: j3 | E1: j4 | F1: j5 | G1: j6 | H1: j7 | I1: j8 | J1: j9 | K1: j12 | L1: j13 | M1: j14 | N1: j15 | O1: j16 | P1: j17 | Q1: j18 | R1: j19 | S1: j20 | T1: j21 | U1: j22 | V1: j23 | W1: j24 | X1: j25 | Y1: j26 | Z1: j27 | AA1: j28 | AB1: j29 | AC1: j30 | AD1: j31 | AE1: j32 | AF1: j33 | AG1: j34 | AH1: j35 | AI1: j36 | AJ1: j37 | AK1: j38 | AL1: j39 | AM1: j40 | AN1: j41 | AO1: j42 | AP1: j43 | AQ1: j44 | AR1: j45
A2: j1 | E2: 1
A3: j2
A4: j3
A5: j4
A6: j5
A7: j6
A8: j7 | I8: 1 | J8: 1 | O8: 1
A9: j8
A10: j9
A11: j12
A12: j13
A13: j14
A14: j15
A15: j16
A16: j17 | O16: 1 | S16: 1
A17: j18
A18: j19
A19: j20
A20: j21
A21: j22
A22: j23
A23: j24
A24: j25
A25: j26
A26: j27
A27: j28
A28: j29 | W28: 1 | Z28: 1 | AA28: 1 | AQ28: 1
A29: j30
A30: j31
A31: j32
A32: j33 | AK32: 1 | AP32: 1
A33: j34
A34: j35
A35: j36
A36: j37
A37: j38
A38: j39
A39: j40
A40: j41
...

Sheet rsiIndex
A1: rsi_par1
A2: rsi_par2
A3: rsi_par3
A4: rsi_par4
A5: Func_typ

Sheet rsiEQ
D1: Func_typ | E1: rsi_par1 | F1: rsi_par2 | G1: rsi_par3 | H1: rsi_par4 | N1: Trout | W1: Base case | AC1: With Sucker
A2: j37 | B2: j1 | C2: t1 | D2: 2 | E2: 0 | F2: 0 | G2: 0 | H2: 1 | N2: Months | O2: Depth (m) | P2: Location | Q2: rsi_par1 | R2: rsi_par2 | S2: rsi_par3 | T2: rsi_par4 | W2: 0.027072261 | X2: 0.99326974 | Y2: 0.42271431 | Z2: 0.050595078 | AC2: 0.027072261 | AD2: 0.99326974 | AE2: 0.42271431 | AF2: 0.050595078
A3: j37 | B3: j1 | C3: t2 | D3: 2 | E3: 0 | F3: 0 | G3: 0 | H3: 1 | M3: Adul/Juv | N3: Sep-Mar | O3: 0.75 – 0.30 | Q3: 0 | R3: 1 | S3: 0.42240891 | T3: 0.04896029 | W3: 0.027072261 | X3: 0.99326974 | Y3: 0.42271431 | Z3: 0.050595078 | AC3: 0.027072261 | AD3: 0.99326974 | AE3: 0.42271431 | AF3: 0.050595078
A4: j37 | B4: j1 | C4: t3 | D4: 2 | E4: 0 | F4: 0 | G4: 0 | H4: 3 | M4: Fry | N4: Apr-Aug | O4: 0.45 – 0.20 | Q4: 0 | R4: 1 | S4: 0.2888249 | T4: 0.01979619 | W4: 0.027072261 | X4: 0.99326974 | Y4: 0.42271431 | Z4: 0.050595078 | AC4: 0.027072261 | AD4: 0.99326974 | AE4: 0.42271431 | AF4: 0.050595078
A5: j37 | B5: j1 | C5: t4 | D5: 2 | E5: 0 | F5: 0 | G5: 0 | H5: 3 | W5: 0.029313504 | X5: 0.98886831 | Y5: 0.24676178 | Z5: 0.024946824 | AC5: 0.029313504 | AD5: 0.98886831 | AE5: 0.24676178 | AF5: 0.024946824
A6: j37 | B6: j1 | C6: t5 | D6: 2 | E6: 0 | F6: 0 | G6: 0 | H6: 3 | W6: 0.029313504 | X6: 0.98886831 | Y6: 0.24676178 | Z6: 0.024946824 | AC6: 0.029313504 | AD6: 0.98886831 | AE6: 0.24676178 | AF6: 0.024946824
A7: j37 | B7: j1 | C7: t6 | D7: 2 | E7: 0 | F7: 0 | G7: 0 | H7: 3 | W7: 0.029313504 | X7: 0.98886831 | Y7: 0.24676178 | Z7: 0.024946824 | AC7: 0.029313504 | AD7: 0.98886831 | AE7: 0.24676178 | AF7: 0.024946824
A8: j37 | B8: j1 | C8: t7 | D8: 2 | E8: 0 | F8: 0 | G8: 0 | H8: 3 | N8: Sucker | W8: 0.029313504 | X8: 0.98886831 | Y8: 0.24676178 | Z8: 0.024946824 | AC8: 0.029313504 | AD8: 0.98886831 | AE8: 0.24676178 | AF8: 0.024946824
A9: j37 | B9: j1 | C9: t8 | D9: 2 | E9: 0 | F9: 0 | G9: 0 | H9: 3 | N9: Months | O9: Depth (m) | Q9: rsi_par1 | R9: rsi_par2 | S9: rsi_par3 | T9: rsi_par4 | W9: 0.029313504 | X9: 0.98886831 | Y9: 0.24676178 | Z9: 0.024946824 | AC9: 0.029313504 | AD9: 0.98886831 | AE9: 0.24676178 | AF9: 0.024946824
A10: j37 | B10: j1 | C10: t9 | D10: 2 | E10: 0 | F10: 0 | G10: 0 | H10: 1 | M10: Adul/Juv | N10: Sep-Mar | O10: 1 | Q10: 0 | R10: 1 | S10: 0.48147111 | T10: 0.10105984 | W10: 0.027072261 | X10: 0.99326974 | Y10: 0.42271431 | Z10: 0.050595078 | AC10: 0.027072261 | AD10: 0.99326974 | AE10: 0.42271431 | AF10: 0.050595078
A11: j37 | B11: j1 | C11: t10 | D11: 2 | E11: 0 | F11: 0 | G11: 0 | H11: 1 | M11: Fy | N11: Apr-Aug | O11: 0.3 | Q11: 0 | R11: 1 | S11: 0.1677217 | T11: 0.031354217 | W11: 0.027072261 | X11: 0.99326974 | Y11: 0.42271431 | Z11: 0.050595078 | AC11: 0.027072261 | AD11: 0.99326974 | AE11: 0.42271431 | AF11: 0.050595078
A12: j37 | B12: j1 | C12: t11 | D12: 2 | E12: 0 | F12: 0 | G12: 0 | H12: 1 | W12: 0.027072261 | X12: 0.99326974 | Y12: 0.42271431 | Z12: 0.050595078 | AC12: 0.027072261 | AD12: 0.99326974 | AE12: 0.42271431 | AF12: 0.050595078
A13: j37 | B13: j1 | C13: t12 | D13: 2 | E13: 0 | F13: 0 | G13: 0 | H13: 1 | W13: 0.027072261 | X13: 0.99326974 | Y13: 0.42271431 | Z13: 0.050595078 | AC13: 0.027072261 | AD13: 0.99326974 | AE13: 0.42271431 | AF13: 0.050595078
A14: j1 | B14: j4 | C14: t1 | D14: 2 | E14: 0 | F14: 0 | G14: 0 | H14: 1 | W14: 0.027072261 | X14: 0.99326974 | Y14: 0.42271431 | Z14: 0.050595078 | AC14: 0.027072261 | AD14: 0.99326974 | AE14: 0.42271431 | AF14: 0.050595078
A15: j1 | B15: j4 | C15: t2 | D15: 2 | E15: 0 | F15: 0 | G15: 0 | H15: 1 | W15: 0.027072261 | X15: 0.99326974 | Y15: 0.42271431 | Z15: 0.050595078 | AC15: 0.027072261 | AD15: 0.99326974 | AE15: 0.42271431 | AF15: 0.050595078
A16: j1 | B16: j4 | C16: t3 | D16: 2 | E16: 0 | F16: 0 | G16: 0 | H16: 3 | W16: 0.027072261 | X16: 0.99326974 | Y16: 0.42271431 | Z16: 0.050595078 | AC16: 0.027072261 | AD16: 0.99326974 | AE16: 0.42271431 | AF16: 0.050595078
A17: j1 | B17: j4 | C17: t4 | D17: 2 | E17: 0 | F17: 0 | G17: 0 | H17: 3 | O17: t1 | P17: 0 | Q17: 1 | R17: 0.42240891 | S17: 0.04896029 | W17: 0.029313504 | X17: 0.98886831 | Y17: 0.24676178 | Z17: 0.024946824 | AC17: 0.029313504 | AD17: 0.98886831 | AE17: 0.24676178 | AF17: 0.024946824
A18: j1 | B18: j4 | C18: t5 | D18: 2 | E18: 0 | F18: 0 | G18: 0 | H18: 3 | O18: t2 | P18: 0 | Q18: 1 | R18: 0.42240891 | S18: 0.04896029 | W18: 0.029313504 | X18: 0.98886831 | Y18: 0.24676178 | Z18: 0.024946824 | AC18: 0.029313504 | AD18: 0.98886831 | AE18: 0.24676178 | AF18: 0.024946824
A19: j1 | B19: j4 | C19: t6 | D19: 2 | E19: 0 | F19: 0 | G19: 0 | H19: 3 | O19: t3 | P19: 0 | Q19: 1 | R19: 0.42240891 | S19: 0.04896029 | W19: 0.029313504 | X19: 0.98886831 | Y19: 0.24676178 | Z19: 0.024946824 | AC19: 0.029313504 | AD19: 0.98886831 | AE19: 0.24676178 | AF19: 0.024946824
A20: j1 | B20: j4 | C20: t7 | D20: 2 | E20: 0 | F20: 0 | G20: 0 | H20: 3 | O20: t4 | P20: 0 | Q20: 1 | R20: 0.2888249 | S20: 0.01979619 | W20: 0.029313504 | X20: 0.98886831 | Y20: 0.24676178 | Z20: 0.024946824 | AC20: 0.029313504 | AD20: 0.98886831 | AE20: 0.24676178 | AF20: 0.024946824
A21: j1 | B21: j4 | C21: t8 | D21: 2 | E21: 0 | F21: 0 | G21: 0 | H21: 3 | O21: t5 | P21: 0 | Q21: 1 | R21: 0.2888249 | S21: 0.01979619 | W21: 0.029313504 | X21: 0.98886831 | Y21: 0.24676178 | Z21: 0.024946824 | AC21: 0.029313504 | AD21: 0.98886831 | AE21: 0.24676178 | AF21: 0.024946824
A22: j1 | B22: j4 | C22: t9 | D22: 2 | E22: 0 | F22: 0 | G22: 0 | H22: 1 | O22: t6 | P22: 0 | Q22: 1 | R22: 0.2888249 | S22: 0.01979619 | W22: 0.027072261 | X22: 0.99326974 | Y22: 0.42271431 | Z22: 0.050595078 | AC22: 0.027072261 | AD22: 0.99326974 | AE22: 0.42271431 | AF22: 0.050595078
A23: j1 | B23: j4 | C23: t10 | D23: 2 | E23: 0 | F23: 0 | G23: 0 | H23: 1 | O23: t7 | P23: 0 | Q23: 1 | R23: 0.2888249 | S23: 0.01979619 | W23: 0.027072261 | X23: 0.99326974 | Y23: 0.42271431 | Z23: 0.050595078 | AC23: 0.027072261 | AD23: 0.99326974 | AE23: 0.42271431 | AF23: 0.050595078
A24: j1 | B24: j4 | C24: t11 | D24: 2 | E24: 0 | F24: 0 | G24: 0 | H24: 1 | O24: t8 | P24: 0 | Q24: 1 | R24: 0.2888249 | S24: 0.01979619 | W24: 0.027072261 | X24: 0.99326974 | Y24: 0.42271431 | Z24: 0.050595078 | AC24: 0.027072261 | AD24: 0.99326974 | AE24: 0.42271431 | AF24: 0.050595078
A25: j1 | B25: j4 | C25: t12 | D25: 2 | E25: 0 | F25: 0 | G25: 0 | H25: 1 | O25: t9 | P25: 0 | Q25: 1 | R25: 0.42240891 | S25: 0.04896029 | W25: 0.027072261 | X25: 0.99326974 | Y25: 0.42271431 | Z25: 0.050595078 | AC25: 0.027072261 | AD25: 0.99326974 | AE25: 0.42271431 | AF25: 0.050595078
A26: j6 | B26: j5 | C26: t1 | D26: 2 | E26: 0 | F26: 0 | G26: 0 | H26: 1 | O26: t10 | P26: 0 | Q26: 1 | R26: 0.42240891 | S26: 0.04896029 | W26: 0.027072261 | X26: 0.99326974 | Y26: 0.42271431 | Z26: 0.050595078 | AC26: 0.027072261 | AD26: 0.99326974 | AE26: 0.42271431 | AF26: 0.050595078
A27: j6 | B27: j5 | C27: t2 | D27: 2 | E27: 0 | F27: 0 | G27: 0 | H27: 1 | O27: t11 | P27: 0 | Q27: 1 | R27: 0.42240891 | S27: 0.04896029 | W27: 0.027072261 | X27: 0.99326974 | Y27: 0.42271431 | Z27: 0.050595078 | AC27: 0.027072261 | AD27: 0.99326974 | AE27: 0.42271431 | AF27: 0.050595078
A28: j6 | B28: j5 | C28: t3 | D28: 2 | E28: 0 | F28: 0 | G28: 0 | H28: 3 | O28: t12 | P28: 0 | Q28: 1 | R28: 0.42240891 | S28: 0.04896029 | W28: 0.027072261 | X28: 0.99326974 | Y28: 0.42271431 | Z28: 0.050595078 | AC28: 0.027072261 | AD28: 0.99326974 | AE28: 0.42271431 | AF28: 0.050595078
A29: j6 | B29: j5 | C29: t4 | D29: 2 | E29: 0 | F29: 0 | G29: 0 | H29: 3 | W29: 0.029313504 | X29: 0.98886831 | Y29: 0.24676178 | Z29: 0.024946824 | AC29: 0.029313504 | AD29: 0.98886831 | AE29: 0.24676178 | AF29: 0.024946824
A30: j6 | B30: j5 | C30: t5 | D30: 2 | E30: 0 | F30: 0 | G30: 0 | H30: 3 | W30: 0.029313504 | X30: 0.98886831 | Y30: 0.24676178 | Z30: 0.024946824 | AC30: 0.029313504 | AD30: 0.98886831 | AE30: 0.24676178 | AF30: 0.024946824
A31: j6 | B31: j5 | C31: t6 | D31: 2 | E31: 0 | F31: 0 | G31: 0 | H31: 3 | W31: 0.029313504 | X31: 0.98886831 | Y31: 0.24676178 | Z31: 0.024946824 | AC31: 0.029313504 | AD31: 0.98886831 | AE31: 0.24676178 | AF31: 0.024946824
A32: j6 | B32: j5 | C32: t7 | D32: 2 | E32: 0 | F32: 0 | G32: 0 | H32: 3 | W32: 0.029313504 | X32: 0.98886831 | Y32: 0.24676178 | Z32: 0.024946824 | AC32: 0.029313504 | AD32: 0.98886831 | AE32: 0.24676178 | AF32: 0.024946824
A33: j6 | B33: j5 | C33: t8 | D33: 2 | E33: 0 | F33: 0 | G33: 0 | H33: 3 | W33: 0.029313504 | X33: 0.98886831 | Y33: 0.24676178 | Z33: 0.024946824 | AC33: 0.029313504 | AD33: 0.98886831 | AE33: 0.24676178 | AF33: 0.024946824
A34: j6 | B34: j5 | C34: t9 | D34: 2 | E34: 0 | F34: 0 | G34: 0 | H34: 1 | W34: 0.027072261 | X34: 0.99326974 | Y34: 0.42271431 | Z34: 0.050595078 | AC34: 0.027072261 | AD34: 0.99326974 | AE34: 0.42271431 | AF34: 0.050595078
A35: j6 | B35: j5 | C35: t10 | D35: 2 | E35: 0 | F35: 0 | G35: 0 | H35: 1 | W35: 0.027072261 | X35: 0.99326974 | Y35: 0.42271431 | Z35: 0.050595078 | AC35: 0.027072261 | AD35: 0.99326974 | AE35: 0.42271431 | AF35: 0.050595078
A36: j6 | B36: j5 | C36: t11 | D36: 2 | E36: 0 | F36: 0 | G36: 0 | H36: 1 | W36: 0.027072261 | X36: 0.99326974 | Y36: 0.42271431 | Z36: 0.050595078 | AC36: 0.027072261 | AD36: 0.99326974 | AE36: 0.42271431 | AF36: 0.050595078
A37: j6 | B37: j5 | C37: t12 | D37: 2 | E37: 0 | F37: 0 | G37: 0 | H37: 1 | W37: 0.027072261 | X37: 0.99326974 | Y37: 0.42271431 | Z37: 0.050595078 | AC37: 0.027072261 | AD37: 0.99326974 | AE37: 0.42271431 | AF37: 0.050595078
A38: j5 | B38: j18 | C38: t1 | D38: 2 | E38: 0 | F38: 0 | G38: 0 | H38: 1 | W38: 0.027072261 | X38: 0.99326974 | Y38: 0.42271431 | Z38: 0.050595078 | AC38: 0.027072261 | AD38: 0.99326974 | AE38: 0.42271431 | AF38: 0.050595078
A39: j5 | B39: j18 | C39: t2 | D39: 2 | E39: 0 | F39: 0 | G39: 0 | H39: 1 | W39: 0.027072261 | X39: 0.99326974 | Y39: 0.42271431 | Z39: 0.050595078 | AC39: 0.027072261 | AD39: 0.99326974 | AE39: 0.42271431 | AF39: 0.050595078
A40: j5 | B40: j18 | C40: t3 | D40: 2 | E40: 0 | F40: 0 | G40: 0 | H40: 3 | W40: 0.027072261 | X40: 0.99326974 | Y40: 0.42271431 | Z40: 0.050595078 | AC40: 0.027072261 | AD40: 0.99326974 | AE40: 0.42271431 | AF40: 0.050595078
...

Sheet RSI_data
A1: Site | B1: Elevation (ft) | C1: Max Water Temperature recorded in (Co) | D1: Preferred Depth for adult BCT (m) | I1: Preferred Depth for fry BCT (m)
D2: [Sep – Mar] | E2: rsi_par1 | F2: rsi_par2 | G2: rsi_par3 | H2: rsi_par4 | I2: [ Apr – Aug ] | J2: rsi_par1 | K2: rsi_par2 | L2: rsi_par3 | M2: rsi_par4
A3: Bear River at Stateline | B3: 4436 | C3: 26.3 | D3: 0.75 – 0.30 | E3: 0 | F3: 1 | G3: 0.42240891 | H3: 0.04896029 | I3: 0.45 – 0.20 | J3: 0 | K3: 1 | L3: 0.2888249 | M3: 0.01979619
F4: 1 | K4: 1
A5: Bear River at Cutler | B5: 4422 | C5: 26.7 | D5: 0.75 – 0.30 | E5: 0 | F5: 1 | G5: 0.42240891 | H5: 0.04896029 | I5: 0.45 – 0.25 | J5: 0 | K5: 1 | L5: 0.2606764 | M5: 0.0418884
E6: 0 | F6: 1 | K6: 1
A7: Bear- Cub Confluence | B7: 4423 | C7: 26.3 | D7: 0.75 – 0.30 | E7: 0 | F7: 1 | G7: 0.42240891 | H7: 0.04896029 | I7: 0.45 – 0.25 | J7: 0 | K7: 1 | L7: 0.2606764 | M7: 0.0418884
E8: 0 | F8: 1 | K8: 1
A9: Bear River below Cutler at UP L Bridge Station #4901980 | B9: 4245 | C9: 25.9 | D9: 0.75 – 0.30 | E9: 0 | F9: 1 | G9: 0.42240891 | H9: 0.04896029 | I9: 0.45 – 0.25 | J9: 0 | K9: 1 | L9: 0.2606764 | M9: 0.0418884
E10: 0 | F10: 1 | K10: 1
A11: Little Bear at Paradise | B11: 4816 | C11: 20.5 | D11: 0.75 – 0.30 | E11: 0 | F11: 1 | G11: 0.42240891 | H11: 0.04896029 | I11: 0.45 – 0.10 | J11: 0 | K11: 1 | L11: 0.14862101 | M11: 0.04447113
E12: 0 | F12: 1 | K12: 1
A13: Little Bear at Mendon | B13: 4414 | C13: 21.4 | D13: 0.75 – 0.30 | E13: 0 | F13: 1 | G13: 0.42240891 | H13: 0.04896029 | I13: 0.45 – 0.10 | J13: 0 | K13: 1 | L13: 0.14862101 | M13: 0.04447113
E14: 0 | F14: 1 | K14: 1
A15: Little Bear near Wellsville | B15: 4493 | C15: 22.2 | D15: 0.75 – 0.30 | E15: 0 | F15: 1 | G15: 0.42240891 | H15: 0.04896029 | I15: 0.45 – 0.10 | J15: 0 | K15: 1 | L15: 0.14862101 | M15: 0.04447113
E16: 0 | F16: 1 | K16: 1

Sheet h
A1: j37 | B1: j1 | C1: t1 | D1: 1
A2: j37 | B2: j1 | C2: t2 | D2: 1
A3: j37 | B3: j1 | C3: t3 | D3: 3
A4: j37 | B4: j1 | C4: t4 | D4: 3
A5: j37 | B5: j1 | C5: t5 | D5: 3
A6: j37 | B6: j1 | C6: t6 | D6: 3
A7: j37 | B7: j1 | C7: t7 | D7: 3 | P7: Brown Trout
A8: j37 | B8: j1 | C8: t8 | D8: 3 | P8: Months | Q8: Depth (m) | R8: h
A9: j37 | B9: j1 | C9: t9 | D9: 1 | O9: Adult | P9: Sep - Feb | Q9: 0.8 | R9: 1
A10: j37 | B10: j1 | C10: t10 | D10: 1 | O10: Fry | P10: Mar-Aug | Q10: 0.5 | R10: 3
A11: j37 | B11: j1 | C11: t11 | D11: 1
A12: j37 | B12: j1 | C12: t12 | D12: 1
A13: j1 | B13: j4 | C13: t1 | D13: 1
A14: j1 | B14: j4 | C14: t2 | D14: 1
A15: j1 | B15: j4 | C15: t3 | D15: 3
A16: j1 | B16: j4 | C16: t4 | D16: 3
A17: j1 | B17: j4 | C17: t5 | D17: 3
A18: j1 | B18: j4 | C18: t6 | D18: 3
A19: j1 | B19: j4 | C19: t7 | D19: 3
A20: j1 | B20: j4 | C20: t8 | D20: 3
A21: j1 | B21: j4 | C21: t9 | D21: 1
A22: j1 | B22: j4 | C22: t10 | D22: 1
... A312: j45 | B312: j32 | C312: t12 | D312: 1

Sheet fciIndex
A1: fci_par1
A2: fci_par2
A3: fci_par3
A4: fci_par4

Sheet fciEQ
D1: fci_par1 | E1: fci_par2 | F1: fci_par3 | G1: fci_par4
A2: j4 | B2: j5 | C2: t1 | D2: 0.001 | E2: 0.001 | F2: 0.001 | G2: 0.001
A3: j4 | B3: j5 | C3: t2 | D3: 0.001 | E3: 0.001 | F3: 0.001 | G3: 0.001
A4: j4 | B4: j5 | C4: t3 | D4: 0.001 | E4: 0.001 | F4: 0.001 | G4: 0.001
A5: j4 | B5: j5 | C5: t4 | D5: 0.014870277 | E5: 1.0113511 | F5: 140.16933 | G5: 14.751512
A6: j4 | B6: j5 | C6: t5 | D6: 0.014870277 | E6: 1.0113511 | F6: 140.16933 | G6: 14.751512
A7: j4 | B7: j5 | C7: t6 | D7: 0.014870277 | E7: 1.0113511 | F7: 140.16933 | G7: 14.751512
A8: j4 | B8: j5 | C8: t7 | D8: 0.014870277 | E8: 1.0113511 | F8: 140.16933 | G8: 14.751512
A9: j4 | B9: j5 | C9: t8 | D9: 0.014870277 | E9: 1.0113511 | F9: 140.16933 | G9: 14.751512
A10: j4 | B10: j5 | C10: t9 | D10: 0.001 | E10: 0.001 | F10: 0.001 | G10: 0.001
A11: j4 | B11: j5 | C11: t10 | D11: 0.001 | E11: 0.001 | F11: 0.001 | G11: 0.001
A12: j4 | B12: j5 | C12: t11 | D12: 0.001 | E12: 0.001 | F12: 0.001 | G12: 0.001
A13: j4 | B13: j5 | C13: t12 | D13: 0.001 | E13: 0.001 | F13: 0.001 | G13: 0.001
... A313: j45 | B313: j32 | C313: t12 | D313: 0.001 | E313: 0.001 | F313: 0.001 | G313: 0.001

Sheet wp
D1: wsi_par1 | E1: wsi_par2
A2: j21 | B2: j23 | C2: t1 | D2: 0.0003 | E2: 0.3373
A3: j21 | B3: j23 | C3: t2 | D3: 2e-05 | E3: 0.4121
A4: j21 | B4: j23 | C4: t3 | D4: 8e-06 | E4: 0.3051
A5: j21 | B5: j23 | C5: t4 | D5: 2e-05 | E5: 0.1373
A6: j21 | B6: j23 | C6: t5 | D6: 3e-06 | E6: 0.1211
A7: j21 | B7: j23 | C7: t6 | D7: 7e-06 | E7: 0.1167
A8: j21 | B8: j23 | C8: t7 | D8: 2e-05 | E8: 0.1396
A9: j21 | B9: j23 | C9: t8 | D9: 3e-05 | E9: 0.1343
A10: j21 | B10: j23 | C10: t9 | D10: 0.0001 | E10: 0.1656
A11: j21 | B11: j23 | C11: t10 | D11: 6e-05 | E11: 0.185
A12: j21 | B12: j23 | C12: t11 | D12: 0.0001 | E12: 0.3932
A13: j21 | B13: j23 | C13: t12 | D13: 0.0001 | E13: 0.401

Sheet Length
A1: j4 | B1: j5 | C1: 14090
A2: j6 | B2: j5 | C2: 470
A3: j5 | B3: j18 | C3: 11513
A4: j21 | B4: j23 | C4: 33740
A5: j37 | B5: j1 | C5: 21736.476
A6: j1 | B6: j4 | C6: 55344.138
A7: j18 | B7: j7 | C7: 13304.681
A8: j7 | B8: j9 | C8: 8267.8962
A9: j12 | B9: j14 | C9: 14391.808
A10: j14 | B10: j17 | C10: 12605.18
A11: j17 | B11: j20 | C11: 56557.259
A12: j19 | B12: j20 | C12: 127172.76
... A26: j45 | B26: j32 | C26: 9264.09

Sheet aw
A1: j21 | B1: j23 | C1: t1 | D1: =118400000/1000000 -> 118.4 | I1: acres | J1: =D1*247.11 -> 29257.824 | L1: 299.46616
A2: j21 | B2: j23 | C2: t2 | D2: =118400000/1000000 -> 118.4 | L2: 299.46616
A3: j21 | B3: j23 | C3: t3 | D3: =118400000/1000000 -> 118.4 | L3: 299.46616
A4: j21 | B4: j23 | C4: t4 | D4: =118400000/1000000 -> 118.4 | L4: 299.46616
A5: j21 | B5: j23 | C5: t5 | D5: =118400000/1000000 -> 118.4 | L5: 299.46616
A6: j21 | B6: j23 | C6: t6 | D6: =118400000/1000000 -> 118.4 | L6: 299.46616
A7: j21 | B7: j23 | C7: t7 | D7: =118400000/1000000 -> 118.4 | L7: 299.46616
A8: j21 | B8: j23 | C8: t8 | D8: =118400000/1000000 -> 118.4 | L8: 299.46616
A9: j21 | B9: j23 | C9: t9 | D9: =118400000/1000000 -> 118.4 | L9: 299.46616
A10: j21 | B10: j23 | C10: t10 | D10: =118400000/1000000 -> 118.4 | L10: 299.46616
A11: j21 | B11: j23 | C11: t11 | D11: =118400000/1000000 -> 118.4 | L11: 299.46616
A12: j21 | B12: j23 | C12: t12 | D12: =118400000/1000000 -> 118.4 | L12: 299.46616
J20: =0.4*J1 -> 11703.13

Sheet lss
C1: t1 | D1: t2 | E1: t3 | F1: t4 | G1: t5 | H1: t6 | I1: t7 | J1: t8 | K1: t9 | L1: t10 | M1: t11 | N1: t12
A2: j37 | B2: j1 | C2: 0 | D2: 0 | E2: 0 | F2: 0 | G2: 0 | H2: 0 | I2: 0 | J2: 0 | K2: 0 | L2: 0 | M2: 0 | N2: 0
A3: j1 | B3: j4 | C3: 0 | D3: 0 | E3: 0 | F3: 0 | G3: 0 | H3: 0 | I3: 0 | J3: 0 | K3: 0 | L3: 0 | M3: 0 | N3: 0
A4: j4 | B4: j5 | C4: 0 | D4: 0 | E4: 0 | F4: 0 | G4: 0 | H4: 0 | I4: 0 | J4: 0 | K4: 0 | L4: 0 | M4: 0 | N4: 0
A5: j6 | B5: j5 | C5: 0 | D5: 0 | E5: 0 | F5: 0 | G5: 0 | H5: 0 | I5: 0 | J5: 0 | K5: 0 | L5: 0 | M5: 0 | N5: 0
A6: j5 | B6: j18 | C6: 0 | D6: 0 | E6: 0 | F6: 0 | G6: 0 | H6: 0 | I6: 0 | J6: 0 | K6: 0 | L6: 0 | M6: 0 | N6: 0
A7: j2 | B7: j3 | C7: 0 | D7: 0 | E7: 0 | F7: 0 | G7: 0 | H7: 0 | I7: 0 | J7: 0 | K7: 0 | L7: 0 | M7: 0 | N7: 0
A8: j4 | B8: j3 | C8: 0 | D8: 0 | E8: 0 | F8: 0 | G8: 0 | H8: 0 | I8: 0 | J8: 0 | K8: 0 | L8: 0 | M8: 0 | N8: 0
A9: j3 | B9: j18 | C9: 0 | D9: 0 | E9: 0 | F9: 0 | G9: 0 | H9: 0 | I9: 0 | J9: 0 | K9: 0 | L9: 0 | M9: 0 | N9: 0
A10: j18 | B10: j7 | C10: 0 | D10: 0 | E10: 0 | F10: 0 | G10: 0 | H10: 0 | I10: 0 | J10: 0 | K10: 0 | L10: 0 | M10: 0 | N10: 0
A11: j34 | B11: j33 | C11: 0 | D11: 0 | E11: 0 | F11: 0 | G11: 0 | H11: 0 | I11: 0 | J11: 0 | K11: 0 | L11: 0 | M11: 0 | N11: 0
A12: j35 | B12: j32 | C12: 0 | D12: 0 | E12: 0 | F12: 0 | G12: 0 | H12: 0 | I12: 0 | J12: 0 | K12: 0 | L12: 0 | M12: 0 | N12: 0
A13: j33 | B13: j32 | C13: 0 | D13: 0 | E13: 0 | F13: 0 | G13: 0 | H13: 0 | I13: 0 | J13: 0 | K13: 0 | L13: 0 | M13: 0 | N13: 0
... A54: j45 | B54: j32 | C54: 0 | D54: 0 | E54: 0 | F54: 0 | G54: 0 | H54: 0 | I54: 0 | J54: 0 | K54: 0 | L54: 0 | M54: 0 | N54: 0

Sheet LinkName
A1: j37 | B1: j1 | C1: 1 | D1: ="L"&C1 -> L1
A2: j1 | B2: j4 | C2: 2 | D2: ="L"&C2 -> L2
A3: j4 | B3: j5 | C3: 3 | D3: ="L"&C3 -> L3
A4: j6 | B4: j5 | C4: 4 | D4: ="L"&C4 -> L4
A5: j5 | B5: j18 | C5: 5 | D5: ="L"&C5 -> L5
A6: j18 | B6: j7 | C6: 7 | D6: ="L"&C6 -> L7
A7: j7 | B7: j9 | C7: 8 | D7: ="L"&C7 -> L8
A8: j9 | B8: j12 | C8: 9 | D8: ="L"&C8 -> L9
A9: j12 | B9: j14 | C9: 11 | D9: ="L"&C9 -> L11
A10: j14 | B10: j17 | C10: 12 | D10: ="L"&C10 -> L12
A11: j17 | B11: j20 | C11: 13 | D11: ="L"&C11 -> L13
A12: j19 | B12: j20 | C12: 14 | D12: ="L"&C12 -> L14
... A26: j45 | B26: j32 | C26: 30 | D26: ="L"&C26 -> L30

Sheet evap
B1: t1 | C1: t2 | D1: t3 | E1: t4 | F1: t5 | G1: t6 | H1: t7 | I1: t8 | J1: t9 | K1: t10 | L1: t11 | M1: t12
A2: j1 | B2: 0 | C2: 0 | D2: 0 | E2: 0.03048 | F2: 0.12192 | G2: 0.1524 | H2: 0.18288 | I2: 0.1524 | J2: 0.09144 | K2: 0.09144 | L2: 0 | M2: 0
A3: j7 | B3: 0 | C3: 0 | D3: 0 | E3: 0.03048 | F3: 0.12192 | G3: 0.1524 | H3: 0.18288 | I3: 0.1524 | J3: 0.09144 | K3: 0.09144 | L3: 0 | M3: 0
A4: j17 | B4: 0 | C4: 0 | D4: 0 | E4: 0.03048 | F4: 0.12192 | G4: 0.1524 | H4: 0.18288 | I4: 0.1524 | J4: 0.09144 | K4: 0.09144 | L4: 0 | M4: 0
A5: j29 | B5: 0 | C5: 0 | D5: 0 | E5: 0.03048 | F5: 0.12192 | G5: 0.1524 | H5: 0.18288 | I5: 0.1524 | J5: 0.09144 | K5: 0.09144 | L5: 0 | M5: 0
A6: j33 | B6: 0 | C6: 0 | D6: 0 | E6: 0.03048 | F6: 0.12192 | G6: 0.1524 | H6: 0.18288 | I6: 0.1524 | J6: 0.09144 | K6: 0.09144 | L6: 0 | M6: 0

Sheet linkEvap
C1: t1 | D1: t2 | E1: t3 | F1: t4 | G1: t5 | H1: t6 | I1: t7 | J1: t8 | K1: t9 | L1: t10 | M1: t11 | N1: t12
A2: j37 | B2: j1 | C2: 0 | D2: 0 | E2: 0 | F2: 0 | G2: 0 | H2: 0 | I2: 0 | J2: 0 | K2: 0 | L2: 0 | M2: 0 | N2: 0
A3: j1 | B3: j4 | C3: 0 | D3: 0 | E3: 0 | F3: 0 | G3: 0 | H3: 0 | I3: 0 | J3: 0 | K3: 0 | L3: 0 | M3: 0 | N3: 0
A4: j4 | B4: j5 | C4: 0 | D4: 0 | E4: 0 | F4: 0 | G4: 0 | H4: 0 | I4: 0 | J4: 0 | K4: 0 | L4: 0 | M4: 0 | N4: 0
A5: j6 | B5: j5 | C5: 0 | D5: 0 | E5: 0 | F5: 0 | G5: 0 | H5: 0 | I5: 0 | J5: 0 | K5: 0 | L5: 0 | M5: 0 | N5: 0
A6: j5 | B6: j18 | C6: 0 | D6: 0 | E6: 0 | F6: 0 | G6: 0 | H6: 0 | I6: 0 | J6: 0 | K6: 0 | L6: 0 | M6: 0 | N6: 0
A7: j2 | B7: j3 | C7: 0 | D7: 0 | E7: 0 | F7: 0 | G7: 0 | H7: 0 | I7: 0 | J7: 0 | K7: 0 | L7: 0 | M7: 0 | N7: 0
A8: j4 | B8: j3 | C8: 0 | D8: 0 | E8: 0 | F8: 0 | G8: 0 | H8: 0 | I8: 0 | J8: 0 | K8: 0 | L8: 0 | M8: 0 | N8: 0
A9: j3 | B9: j18 | C9: 0 | D9: 0 | E9: 0 | F9: 0 | G9: 0 | H9: 0 | I9: 0 | J9: 0 | K9: 0 | L9: 0 | M9: 0 | N9: 0
A10: j18 | B10: j7 | C10: 0 | D10: 0 | E10: 0 | F10: 0 | G10: 0 | H10: 0 | I10: 0 | J10: 0 | K10: 0 | L10: 0 | M10: 0 | N10: 0
A11: j34 | B11: j33 | C11: 0 | D11: 0 | E11: 0 | F11: 0 | G11: 0 | H11: 0 | I11: 0 | J11: 0 | K11: 0 | L11: 0 | M11: 0 | N11: 0
A12: j35 | B12: j32 | C12: 0 | D12: 0 | E12: 0 | F12: 0 | G12: 0 | H12: 0 | I12: 0 | J12: 0 | K12: 0 | L12: 0 | M12: 0 | N12: 0
A13: j33 | B13: j32 | C13: 0 | D13: 0 | E13: 0 | F13: 0 | G13: 0 | H13: 0 | I13: 0 | J13: 0 | K13: 0 | L13: 0 | M13: 0 | N13: 0
... A55: j45 | B55: j32 | C55: 0 | D55: 0 | E55: 0 | F55: 0 | G55: 0 | H55: 0 | I55: 0 | J55: 0 | K55: 0 | L55: 0 | M55: 0 | N55: 0

Sheet evap_WEAP
B1: t1 | C1: t2 | D1: t3 | E1: t4 | F1: t5 | G1: t6 | H1: t7 | I1: t8 | J1: t9 | K1: t10 | L1: t11 | M1: t12
A2: j1 | B2: 0 | C2: 0 | D2: 0 | E2: 0.03048 | F2: 0.12192 | G2: 0.1524 | H2: 0.18288 | I2: 0.1524 | J2: 0.09144 | K2: 0.09144 | L2: 0 | M2: 0
A3: j7 | B3: 0 | C3: 0 | D3: 0 | E3: 0.03048 | F3: 0.12192 | G3: 0.1524 | H3: 0.18288 | I3: 0.1524 | J3: 0.09144 | K3: 0.09144 | L3: 0 | M3: 0
A4: j17 | B4: 0 | C4: 0 | D4: 0 | E4: 0.03048 | F4: 0.12192 | G4: 0.1524 | H4: 0.18288 | I4: 0.1524 | J4: 0.09144 | K4: 0.09144 | L4: 0 | M4: 0
A5: j29 | B5: 0 | C5: 0 | D5: 0 | E5: 0.03048 | F5: 0.12192 | G5: 0.1524 | H5: 0.18288 | I5: 0.1524 | J5: 0.09144 | K5: 0.09144 | L5: 0 | M5: 0
A6: j33 | B6: 0 | C6: 0 | D6: 0 | E6: 0.03048 | F6: 0.12192 | G6: 0.1524 | H6: 0.18288 | I6: 0.1524 | J6: 0.09144 | K6: 0.09144 | L6: 0 | M6: 0

Sheet ResElevVol
B1: RA_par1 | C1: RA_par2 | D1: RA_par3
A2: j1 | B2: 0.5802 | C2: 8.8779 | D2: 0.04744
A3: j7 | B3: 0.1718 | C3: 0.0521 | D3: 3.0042
A4: j17 | B4: 0.1718 | C4: 0.0521 | D4: 3.0042
A5: j29 | B5: -0.0004 | C5: 0.0694 | D5: 0.4076
A6: j33 | B6: 0.001 | C6: 0.0295 | D6: 0.0897
A17: j33 | B17: 0.001 | C17: 0.0295 | D17: 0.0897

Sheet EvaporationCurve
B1: STOR (m3) | C1: elevation (m) | D1: area (m) | E1: At+Ab | I1: Old elevation at STOR=0
A2: 0 | B2: 0 | C2: 1399.032 | D2: 0 | E2: =(B3-B2/C3-C2)*2 -> 317907.22 | I2: 1399.032
A3: 1 | B3: 160352.64 | C3: 1402.08 | D3: =E2-D2 -> 317907.22 | E3: =(B4-B3/C4-C3)*2 -> 1598027
A4: 2 | B4: 800529.72 | C4: 1405.128 | D4: =E3-D3 -> 1280119.8 | E4: =(B5-B4/C5-C4)*2 -> 4286102.7
A5: 3 | B5: 2145024.9 | C5: 1408.176 | D5: =E4-D4 -> 3005982.8 | E5: =(B6-B5/C6-C5)*2 -> 8519970.3
A6: 4 | B6: 4262913.3 | C6: 1411.224 | D6: =E5-D5 -> 5513987.5 | E6: =(B7-B6/C7-C6)*2 -> 14637513
A7: 5 | B7: 7323181.8 | C7: 1414.272 | D7: =E6-D6 -> 9123525.2 | E7: =(B8-B7/C8-C7)*2 -> 22771714
A8: 6 | B8: 11392438 | C8: 1417.32 | D8: =E7-D7 -> 13648189 | E8: =(B9-B8/C9-C8)*2 -> 32559847
A9: 7 | B9: 16289361 | C9: 1420.368 | D9: =E8-D8 -> 18911657 | E9: =(B10-B9/C10-C9)*2 -> 43691335
A10: 8 | B10: 21858532 | C10: 1423.416 | D10: =E9-D9 -> 24779678 | E10: =(B11-B10/C11-C10)*2 -> 46059204
A11: 9 | B11: 23046375 | C11: 1424.0256 | D11: =E10-D10 -> 21279525 | E11: =(B12-B11/C12-C11)*2 -> 55718219
A12: 10 | B12: 27876690 | C12: 1426.464 | D12: =E11-D11 -> 34438694 | E12: =(B13-B12/C13-C12)*2 -> 69279826
A13: 11 | B13: 34660840 | C13: 1429.512 | D13: =E12-D12 -> 34841132 | E13: =(B14-B13/C14-C13)*2 -> 84072213
A14: 12 | B14: 42061731 | C14: 1432.56 | D14: =E13-D13 -> 49231082 | E14: =(B15-B14/C15-C14)*2 -> 1.0034396e+08
... A18: 16 | B18: 79559580 | C18: 1444.752 | D18: =E17-D17 -> 88431282 | E18: =(B19-B18/C19-C18)*2 -> 1.8219582e+08
A19: 17 | B19: 91154309 | C19: 1447.8 | D19: =E18-D18 -> 93764542 | E19: =(B19/C19)*2 -> 125921.13
A25: j30 | B25: MillCreek | I25: WEAP Data
B26: STOR (m3) | C26: elevation (m) | D26: area (m) | E26: At+Ab | F26: Month | G26: evap(m) | I26: STOR (AF) | J26: elevation (ft) | L26: Month | M26: evap(ft)
B27: =I27*1233.48/1000000 -> 0 | C27: =J27*0.3048 -> 1690.4208 | D27: 0 | E27: =(B28-B27)/(C28-C27)*2*1000000 -> 19078.009 | F27: t1 | G27: =M27*0.3048 -> 0 | I27: 0 | J27: 5546 | L27: t1 | M27: 0
B28: =I28*1233.48/1000000 -> 0.04070484 | C28: =J28*0.3048 -> 1694.688 | D28: =(E27-D27)/1000000 -> 0.019078009 | E28: =(B29-B28)/(C29-C28)*2*1000000 -> 142044.45 | F28: t2 | G28: =M28*0.3048 -> 0 | I28: 33 | J28: 5560 | L28: t2 | M28: 0
B29: =I29*1233.48/1000000 -> 0.47365632 | C29: =J29*0.3048 -> 1700.784 | D29: =(E28-D28)/1000000 -> 0.14204443 | E29: =(B30-B29)/(C30-C29)*2*1000000 -> 297848.19 | F29: t3 | G29: =M29*0.3048 -> 0 | I29: 384 | J29: 5580 | L29: t3 | M29: 0
B30: =I30*1233.48/1000000 -> 1.3814976 | C30: =J30*0.3048 -> 1706.88 | D30: =(E29-D29)/1000000 -> 0.29784805 | E30: =(B31-B30)/(C31-C30)*2*1000000 -> 475909.61 | F30: t4 | G30: =M30*0.3048 -> 0.03048 | I30: 1120 | J30: 5600 | L30: t4 | M30: 0.1
B31: =I31*1233.48/1000000 -> 2.8320701 | C31: =J31*0.3048 -> 1712.976 | D31: =(E30-D30)/1000000 -> 0.47590931 | E31: =(B32-B31)/(C32-C31)*2*1000000 -> 698486.38 | F31: t5 | G31: =M31*0.3048 -> 0.12192 | I31: 2296 | J31: 5620 | L31: t5 | M31: 0.4
B32: =I32*1233.48/1000000 -> 4.9610566 | C32: =J32*0.3048 -> 1719.072 | D32: =(E31-D31)/1000000 -> 0.6984859 | E32: =(B33-B32)/(C33-C32)*2*1000000 -> 985812.76 | F32: t6 | G32: =M32*0.3048 -> 0.1524 | I32: 4022 | J32: 5640 | L32: t6 | M32: 0.5
B33: =I33*1233.48/1000000 -> 7.9658138 | C33: =J33*0.3048 -> 1725.168 | D33: =(E32-D32)/1000000 -> 0.98581206 | E33: =(B34-B33)/(C34-C33)*2*1000000 -> 1573415.4 | F33: t7 | G33: =M33*0.3048 -> 0.18288 | I33: 6458 | J33: 5660 | L33: t7 | M33: 0.6
B34: =I34*1233.48/1000000 -> 12.761584 | C34: =J34*0.3048 -> 1731.264 | D34: =(E33-D33)/1000000 -> 1.5734144 | E34: =(B35-B34)/(C35-C34)*2*1000000 -> 2167088.4 | F34: t8 | G34: =M34*0.3048 -> 0.1524 | I34: 10346 | J34: 5680 | L34: t8 | M34: 0.5
B35: =I35*1233.48/1000000 -> 19.366869 | C35: =J35*0.3048 -> 1737.36 | D35: =(E34-D34)/1000000 -> 2.1670868 | E35: =(B36-B35)/(C36-C35)*2*1000000 -> 2838865.6 | F35: t9 | G35: =M35*0.3048 -> 0.09144 | I35: 15701 | J35: 5700 | L35: t9 | M35: 0.3
B36: =I36*1233.48/1000000 -> 28.019732 | C36: =J36*0.3048 -> 1743.456 | D36: =(E35-D35)/1000000 -> 2.8388634 | E36: =(B37-B36)/(C37-C36)*2*1000000 -> 3569726.7 | F36: t10 | G36: =M36*0.3048 -> 0.09144 | I36: 22716 | J36: 5720 | L36: t10 | M36: 0.3
B37: =I37*1233.48/1000000 -> 38.900259 | C37: =J37*0.3048 -> 1749.552 | D37: =(E36-D36)/1000000 -> 3.5697239 | E37: =(B38-B37)/(C38-C37)*2*1000000 -> 4366146.9 | F37: t11 | G37: =M37*0.3048 -> 0 | I37: 31537 | J37: 5740 | L37: t11 | M37: 0
B38: =I38*1233.48/1000000 -> 52.208274 | C38: =J38*0.3048 -> 1755.648 | D38: =(E37-D37)/1000000 -> 4.3661433 | E38: =(B39-B38)/(C39-C38)*2*1000000 -> 5181991.9 | F38: t12 | G38: =M38*0.3048 -> 0 | I38: 42326 | J38: 5760 | L38: t12 | M38: 0
B39: =I39*1233.48/1000000 -> 68.002986 | C39: =J39*0.3048 -> 1761.744 | D39: =(E38-D38)/1000000 -> 5.1819876 | E39: =(B40-B39)/(C40-C39)*2*1000000 -> 6052064.8 | I39: 55131 | J39: 5780
B40: =I40*1233.48/1000000 -> 86.449679 | C40: =J40*0.3048 -> 1767.84 | D40: =(E39-D39)/1000000 -> 6.0520596 | E40: =(B41-B40)/(C41-C40)*2*1000000 -> 97802.606 | I40: 70086 | J40: 5800
A45: j7 | B45: Cutler | I45: WEAP Data
B46: STOR (m3) | C46: elevation (m) | D46: area (m) | E46: At+Ab | F46: Month | G46: evap(m) | I46: STOR (AF) | J46: elevation (ft) | L46: Month | M46: evap(ft)
B47: =I47*1233.48/1000000 -> 0 | C47: =J47*0.3048 -> 1284.1224 | D47: 0 | E47: =(B48-B47)/(C48-C47)*2*1000000 -> 3570750.3 | F47: t1 | G47: =M47*0.3048 -> 0 | I47: 0 | J47: 4213 | L47: t1 | M47: 0
B48: =I48*1233.48/1000000 -> 9.2511 | C48: =J48*0.3048 -> 1289.304 | D48: =(E47-D47)/1000000 -> 3.5707503 | E48: =(B49-B48)/(C49-C48)*2*1000000 -> 11128839 | F48: t2 | G48: =M48*0.3048 -> 0 | I48: 7500 | J48: 4230 | L48: t2 | M48: 0
B49: =I49*1233.48/1000000 -> 26.21145 | C49: =J49*0.3048 -> 1292.352 | D49: =(E48-D48)/1000000 -> 11.128835 | E49: =(B50-B49)/(C50-C49)*2*1000000 -> 17199114 | F49: t3 | G49: =M49*0.3048 -> 0 | I49: 21250 | J49: 4240 | L49: t3 | M49: 0
B50: =I50*1233.48/1000000 -> 52.4229 | C50: =J50*0.3048 -> 1295.4 | D50: =(E49-D49)/1000000 -> 17.199103 | E50: =(B51-B50)/(C51-C50)*2*1000000 -> 22257677 | F50: t4 | G50: =M50*0.3048 -> 0.03048 | I50: 42500 | J50: 4250 | L50: t4 | M50: 0.1
B51: =I51*1233.48/1000000 -> 86.3436 | C51: =J51*0.3048 -> 1298.448 | D51: =(E50-D50)/1000000 -> 22.25766 | E51: =(B52-B51)/(C52-C51)*2*1000000 -> 25292815 | F51: t5 | G51: =M51*0.3048 -> 0.12192 | I51: 70000 | J51: 4260 | L51: t5 | M51: 0.4
B52: =I52*1233.48/1000000 -> 117.1806 | C52: =J52*0.3048 -> 1300.8864 | D52: =(E51-D51)/1000000 -> 25.292793 | E52: =(B53-B52)/(C53-C52)*2*1000000 -> 28906074 | F52: t6 | G52: =M52*0.3048 -> 0.1524 | I52: 95000 | J52: 4268 | L52: t6 | M52: 0.5
...

Sheet Cons
B1: t1 | C1: t2 | D1: t3 | E1: t4 | F1: t5 | G1: t6 | H1: t7 | I1: t8 | J1: t9 | K1: t10 | L1: t11 | M1: t12 | R1: Value in WEAP
A2: j3 | B2: 0.27 | C2: 0.27 | D2: 0.27 | E2: 0.73 | F2: 0.73 | G2: 0.73 | H2: 0.73 | I2: 0.73 | J2: 0.73 | K2: 0.73 | L2: 0.27 | M2: 0.27 | R2: Y | S2: j3 | T2: Cache M&I
A3: j8 | B3: 1 | C3: 1 | D3: 1 | E3: 1 | F3: 1 | G3: 1 | H3: 1 | I3: 1 | J3: 1 | K3: 1 | L3: 1 | M3: 1 | R3: N | S3: j8 | T3: BRCC
A4: j13 | B4: 0.27 | C4: 0.27 | D4: 0.27 | E4: 0.73 | F4: 0.73 | G4: 0.73 | H4: 0.73 | I4: 0.73 | J4: 0.73 | K4: 0.73 | L4: 0.27 | M4: 0.27 | R4: N | S4: j13 | T4: Box Elder M&I
A5: j16 | B5: 1 | C5: 1 | D5: 1 | E5: 1 | F5: 1 | G5: 1 | H5: 1 | I5: 1 | J5: 1 | K5: 1 | L5: 1 | M5: 1 | R5: N | S5: j16 | T5: Wasatch Front
A6: j15 | B6: 1 | C6: 1 | D6: 1 | E6: 1 | F6: 1 | G6: 1 | H6: 1 | I6: 1 | J6: 1 | K6: 1 | L6: 1 | M6: 1 | R6: N | S6: j15 | T6: Box Elder Ag
A7: j28 | B7: 1 | C7: 1 | D7: 1 | E7: 1 | F7: 1 | G7: 1 | H7: 1 | I7: 1 | J7: 1 | K7: 1 | L7: 1 | M7: 1 | R7: N | S7: j28 | T7: South Cache M&I
A8: j27 | B8: 0.27 | C8: 0.27 | D8: 0.27 | E8: 0.73 | F8: 0.73 | G8: 0.73 | H8: 0.73 | I8: 0.73 | J8: 0.73 | K8: 0.73 | L8: 0.27 | M8: 0.27 | R8: N | S8: j27 | T8: South Cache New
A9: j39 | B9: 1 | C9: 1 | D9: 1 | E9: 1 | F9: 1 | G9: 1 | H9: 1 | I9: 1 | J9: 1 | K9: 1 | L9: 1 | M9: 1 | R9: Y | S9: j39 | T9: Cache Ag
A10: j38 | B10: 1 | C10: 1 | D10: 1 | E10: 1 | F10: 1 | G10: 1 | H10: 1 | I10: 1 | J10: 1 | K10: 1 | L10: 1 | M10: 1
A11: j41 | B11: 0.27 | C11: 0.27 | D11: 0.27 | E11: 0.73 | F11: 0.73 | G11: 0.73 | H11: 0.73 | I11: 0.73 | J11: 0.73 | K11: 0.73 | L11: 0.27 | M11: 0.27
A12: j42 | B12: 0.27 | C12: 0.27 | D12: 0.27 | E12: 0.73 | F12: 0.73 | G12: 0.73 | H12: 0.73 | I12: 0.73 | J12: 0.73 | K12: 0.73 | L12: 0.27 | M12: 0.27
A13: j44 | B13: 0.27 | C13: 0.27 | D13: 0.27 | E13: 0.73 | F13: 0.73 | G13: 0.73 | H13: 0.73 | I13: 0.73 | J13: 0.73 | K13: 0.73 | L13: 0.27 | M13: 0.27

Sheet inactive
A1: j1 | B1: 0
A2: j7 | B2: 0
A3: j17 | B3: 0
A4: j29 | B4: 4.2 | F4: 4.2
A5: j33 | B5: =2000*1233.48/1000000 -> 2.46696 | F5: =2000*1233.48/1000000 -> 2.46696

Sheet capacity
A1: j1 | B1: 0
A2: j7 | B2: 0
A3: j17 | B3: 0
A4: j29 | B4: =23046340/1000000 -> 23.04634 | G4: =23046340/1000000 -> 23.04634
A5: j33 | B5: =13000*1233.48/1000000 -> 16.03524 | G5: =13000*1233.48/1000000 -> 16.03524

Sheet InStor
A1: j1 | B1: 0 | G1: WEAP
A2: j7 | B2: 0
A3: j17 | B3: 0
A4: j29 | B4: 5 | F4: 5 | H4: 12.796141
A5: j33 | B5: 3 | F5: 3 | H5: 3

Sheet demandReq
B1: t1 | C1: t2 | D1: t3 | E1: t4 | F1: t5 | G1: t6 | H1: t7 | I1: t8 | J1: t9 | K1: t10 | L1: t11 | M1: t12
A2: j3 | B2: 2.376916 | C2: 2.376916 | D2: 2.376916 | E2: 8.8748886 | F2: 8.8748886 | G2: 8.8748886 | H2: 8.8748886 | I2: 8.8748886 | J2: 8.8748886 | K2: 8.8748886 | L2: 2.376916 | M2: 2.376916
A3: j8 | B3: 1.575154 | C3: 0.97074876 | D3: 0.36757704 | E3: 3.1379731 | F3: 42.490919 | G3: 56.682106 | H3: 59.722265 | I3: 56.020529 | J3: 43.834179 | K3: 20.588015 | L3: 5.6444045 | M3: 1.9254623
A4: j13 | B4: 0 | C4: 0 | D4: 0 | E4: 0 | F4: 0 | G4: 0 | H4: 0 | I4: 0 | J4: 0 | K4: 0 | L4: 0 | M4: 0
A5: j16 | B5: 0 | C5: 0 | D5: 0 | E5: 0 | F5: 0 | G5: 0 | H5: 0 | I5: 0 | J5: 0 | K5: 0 | L5: 0 | M5: 0
A6: j15 | B6: 0 | C6: 0 | D6: 0 | E6: 0 | F6: 0 | G6: 0 | H6: 0 | I6: 0 | J6: 0 | K6: 0 | L6: 0 | M6: 0
A7: j28 | B7: =B25*0.0744661151309 -> 0 | C7: =C25*0.0744661151309 -> 0 | D7: =D25*0.0744661151309 -> 0 | E7: =E25*0.0744661151309 -> 0 | F7: =F25*0.0744661151309 -> 1.6015534 | G7: =G25*0.0744661151309 -> 2.1768928 | H7: =H25*0.0744661151309 -> 2.0624712 | I7: =I25*0.0744661151309 -> 1.8378718 | ... M7: =M25*0.0744661151309 -> 0
A8: j27 | B8: =B26*0.0744661151309 -> 0 | C8: =C26*0.0744661151309 -> 0 | D8: =D26*0.0744661151309 -> 0 | E8: =E26*0.0744661151309 -> 0 | F8: =F26*0.0744661151309 -> 0 | G8: =G26*0.0744661151309 -> 0 | H8: =H26*0.0744661151309 -> 0 | I8: =I26*0.0744661151309 -> 0 | ... M8: =M26*0.0744661151309 -> 0
A9: j39 | B9: =B27*0.0744661151309 -> 0 | C9: =C27*0.0744661151309 -> 0 | D9: =D27*0.0744661151309 -> 0 | E9: =E27*0.0744661151309 -> 0 | F9: =F27*0.0744661151309 -> 0 | G9: =G27*0.0744661151309 -> 0 | H9: =H27*0.0744661151309 -> 0 | I9: =I27*0.0744661151309 -> 0 | ... M9: =M27*0.0744661151309 -> 0
A10: j38 | B10: =B28*0.0744661151309 -> 0 | C10: =C28*0.0744661151309 -> 0 | D10: =D28*0.0744661151309 -> 0 | E10: =E28*0.0744661151309 -> 0 | F10: =F28*0.0744661151309 -> 2.8759877 | G10: =G28*0.0744661151309 -> 2.4447226 | H10: =H28*0.0744661151309 -> 1.9548556 | I10: =I28*0.0744661151309 -> 1.7756565 | ... M10: =M28*0.0744661151309 -> 0
A11: j41 | B11: =B29*0.0744661151309 -> 0 | C11: =C29*0.0744661151309 -> 0 | D11: =D29*0.0744661151309 -> 0 | E11: =E29*0.0744661151309 -> 0 | F11: =F29*0.0744661151309 -> 0.89566779 | G11: =G29*0.0744661151309 -> 1.7569039 | H11: =H29*0.0744661151309*0.5 -> 1.2348163 | I11: =I29*0.0744661151309*0.3 -> 0.72345032 | J11: 0 | K11: =K29*0.0744661151309 -> 0 | L11: =L29*0.0744661151309 -> 0 | M11: =M29*0.0744661151309 -> 0
A12: j42 | B12: =B30*0.0744661151309 -> 0 | C12: =C30*0.0744661151309 -> 0 | D12: =D30*0.0744661151309 -> 0 | E12: =E30*0.0744661151309 -> 0 | F12: =F30*0.0744661151309 -> 2.8759877 | G12: =G30*0.0744661151309 -> 2.4447226 | H12: =H30*0.0744661151309 -> 1.9548556 | I12: =I30*0.0744661151309 -> 1.7756565 | ... M12: =M30*0.0744661151309 -> 0
A13: j44 | B13: =B31*0.0744661151309 -> 0 | C13: =C31*0.0744661151309 -> 0 | D13: =D31*0.0744661151309 -> 0 | E13: =E31*0.0744661151309 -> 0 | F13: =F31*0.0744661151309 -> 2.4287711 | G13: =G31*0.0744661151309 -> 4.3567642 | H13: =H31*0.0744661151309 -> 4.2909297 | I13: =I31*0.0744661151309 -> 3.0648812 | ... M13: =M31*0.0744661151309 -> 0
A24: cfs
A25: j28 | B25: 0 | C25: 0 | D25: 0 | E25: 0 | F25: 21.507143 | G25: 29.233333 | H25: 27.696774 | I25: 24.680645 | J25: 13.956667 | K25: 0 | L25: 0 | M25: 0
A26: j27 | B26: 0 | C26: 0 | D26: 0 | E26: 0 | F26: 0 | G26: 0 | H26: 0 | I26: 0 | J26: 0 | K26: 0 | L26: 0 | M26: 0
A27: j39 | B27: 0 | C27: 0 | D27: 0 | E27: 0 | F27: 0 | G27: 0 | H27: 0 | I27: 0 | J27: 0 | K27: 0 | L27: 0 | M27: 0
A28: j38 | F28: 38.621429 | G28: 32.83 | H28: 26.251613 | I28: 23.845161 | J28: 13.023333
A29: j41 | F29: 12.027857 | G29: 23.593333 | H29: 33.164516 | I29: 32.383871 | J29: 13.22
A30: j42 | F30: 38.621429 | G30: 32.83 | H30: 26.251613 | I30: 23.845161 | J30: 13.023333
A31: j44 | F31: 32.615789 | G31: 58.506667 | H31: 57.622581 | I31: 41.158065 | J31: 0
A45: j28 | E45: Old | F45: 3.7716555 | G45: 4.2016264 | H45: 4.4244883 | I45: 4.1871576 | J45: 1.9542391

Sheet Instream
C1: t1 | D1: t2 | E1: t3 | F1: t4 | G1: t5 | H1: t6 | I1: t7 | J1: t8 | K1: t9 | L1: t10 | M1: t11 | N1: t12
A2: j37 | B2: j1 | C2: 0 | D2: 0 | E2: 0 | F2: 0 | G2: 0 | H2: 0 | I2: 0 | J2: 0 | K2: 0 | L2: 0 | M2: 0 | N2: 0
A3: j1 | B3: j4 | C3: 0 | D3: 0 | E3: 0 | F3: 0 | G3: 0 | H3: 0 | I3: 0 | J3: 0 | K3: 0 | L3: 0 | M3: 0 | N3: 0
A4: j4 | B4: j5 | C4: 0 | D4: 0 | E4: 0 | F4: 0 | G4: 0 | H4: 0 | I4: 0 | J4: 0 | K4: 0 | L4: 0 | M4: 0 | N4: 0
A5: j6 | B5: j5 | C5: 0 | D5: 0 | E5: 0 | F5: 0 | G5: 0 | H5: 0 | I5: 0 | J5: 0 | K5: 0 | L5: 0 | M5: 0 | N5: 0
A6: j5 | B6: j18 | C6: 0 | D6: 0 | E6: 0 | F6: 0 | G6: 0 | H6: 0 | I6: 0 | J6: 0 | K6: 0 | L6: 0 | M6: 0 | N6: 0
A7: j18 | B7: j7 | C7: 0 | D7: 0 | E7: 0 | F7: 0 | G7: 0 | H7: 0 | I7: 0 | J7: 0 | K7: 0 | L7: 0 | M7: 0 | N7: 0
A8: j7 | B8: j9 | C8: 0 | D8: 0 | E8: 0 | F8: 0 | G8: 0 | H8: 0 | I8: 0 | J8: 0 | K8: 0 | L8: 0 | M8: 0 | N8: 0
A9: j9 | B9: j12 | C9: 0 | D9: 0 | E9: 0 | F9: 0 | G9: 0 | H9: 0 | I9: 0 | J9: 0 | K9: 0 | L9: 0 | M9: 0 | N9: 0
A10: j12 | B10: j14 | C10: 0 | D10: 0 | E10: 0 | F10: 0 | G10: 0 | H10: 0 | I10: 0 | J10: 0 | K10: 0 | L10: 0 | M10: 0 | N10: 0
A11: j14 | B11: j17 | C11: 0 | D11: 0 | E11: 0 | F11: 0 | G11: 0 | H11: 0 | I11: 0 | J11: 0 | K11: 0 | L11: 0 | M11: 0 | N11: 0
A12: j17 | B12: j20 | C12: 0 | D12: 0 | E12: 0 | F12: 0 | G12: 0 | H12: 0 | I12: 0 | J12: 0 | K12: 0 | L12: 0 | M12: 0 | N12: 0
A13: j19 | B13: j20 | C13: 0 | D13: 0 | E13: 0 | F13: 0 | G13: 0 | H13: 0 | I13: 0 | J13: 0 | K13: 0 | L13: 0 | M13: 0 | N13: 0
... A27: j45 | B27: j32 | C27: 0 | D27: 0 | E27: 0 | F27: 0 | G27: 0 | H27: 0 | I27: 0 | J27: 0 | K27: 0 | L27: 0 | M27: 0 | N27: 0

Sheet divCap
A1: j4 | B1: j39 | C1: 100000
A2: j7 | B2: j16 | C2: 100000
A3: j7 | B3: j8 | C3: 100000
A4: j17 | B4: j16 | C4: 100000
A5: j29 | B5: j44 | C5: 100000
A6: j29 | B6: j28 | C6: 100000
A7: j12 | B7: j13 | C7: 100000
A8: j12 | B8: j15 | C8: 100000
A9: j30 | B9: j27 | C9: 100000
A10: j4 | B10: j3 | C10: 100000
A11: j45 | B11: j42 | C11: 100000
A12: j43 | B12: j41 | C12: 100000
A13: j33 | B13: j38 | C13: 100000

Sheet StageFlow
C1: sf_par1 | D1: sf_par2 | K1: Old | L1: Old
A2: j4 | B2: j5 | C2: 0.0117 | D2: 0.9086 | K2: 0.0117 | L2: 0.9086
A3: j6 | B3: j5 | C3: 0.0222 | D3: 1.5952 | K3: 0.0222 | L3: 1.5952
A4: j5 | B4: j18 | C4: 0.0142 | D4: 1.181 | K4: 0.0142 | L4: 1.181
A5: j21 | B5: j23 | C5: 0.0121 | D5: 0.6608 | K5: 0.0121 | L5: 0.6608
A6: j37 | B6: j1 | C6: 0.0083 | D6: 0.7054 | K6: 0.0083 | L6: 0.7054
A7: j1 | B7: j4 | C7: 0.0083 | D7: 0.7054 | K7: 0.0083 | L7: 0.7054
A8: j18 | B8: j7 | C8: 0.0121 | D8: 0.3608 | K8: 0.0121 | L8: 0.3608
A9: j7 | B9: j9 | C9: 0.0121 | D9: 0.3608 | K9: 0.0121 | L9: 0.3608
A10: j12 | B10: j14 | C10: 0.0121 | D10: 0.3608 | K10: 0.0121 | L10: 0.3608
A11: j14 | B11: j17 | C11: 0.0121 | D11: 0.3608 | K11: 0.0121 | L11: 0.3608
A12: j17 | B12: j20 | C12: 0.0121 | D12: 0.3608 | K12: 0.0121 | L12: 0.3608
A13: j19 | B13: j20 | C13: 0.0256 | D13: 0.2982 | K13: 0.0256 | L13: 0.2982
... A27: j45 | B27: j32 | C27: 0.0505 | D27: 0.357 | K27: 0.0217 | L27: 1.0789

Sheet WidthFlow
C1: wf_par1 | D1: wf_par2 | L1: Old values
A2: j4 | B2: j5 | C2: 0.0822 | D2: 32.695 | L2: 24.762 | M2: 0.1031
A3: j6 | B3: j5 | C3: 0.2618 | D3: 9.0059 | L3: 8.8047 | M3: 0.1246
A4: j5 | B4: j18 | C4: 0.1234 | D4: 29.276 | L4: 18.932 | M4: 0.1618
A5: j21 | B5: j23 | C5: 0.1618 | D5: 18.932 | L5: 18.932 | M5: 0.1618
A6: j37 | B6: j1 | C6: 0.1031 | D6: 24.762 | L6: 24.762 | M6: 0.1031
A7: j1 | B7: j4 | C7: 0.1031 | D7: 24.762 | L7: 24.762 | M7: 0.1031
A8: j18 | B8: j7 | C8: 0.1618 | D8: 18.932 | L8: 18.932 | M8: 0.1618
A9: j7 | B9: j9 | C9: 0.1618 | D9: 28.221 | L9: 18.932 | M9: 0.1618
A10: j12 | B10: j14 | C10: 0.1618 | D10: 28.221 | L10: 18.932 | M10: 0.1618
A11: j14 | B11: j17 | C11: 0.1618 | D11: 28.221 | L11: 18.932 | M11: 0.1618
A12: j17 | B12: j20 | C12: 0.1618 | D12: 28.221 | L12: 18.932 | M12: 0.1618
A13: j19 | B13: j20 | C13: 0.1618 | D13: 28.221 | L13: 18.932 | M13: 0.1618
... A27: j45 | B27: j32 | C27: 0.1618 | D27: 15.32 | L27: 18.932 | M27: 0.1618

Sheet Revegetate
D1: cottonwood
A2: j4 | B2: j5 | C2: t1 | D2: 0
A3: j4 | B3: j5 | C3: t2 | D3: 0
A4: j4 | B4: j5 | C4: t3 | D4: 0.05
A5: j4 | B5: j5 | C5: t4 | D5: 0.1
A6: j4 | B6: j5 | C6: t5 | D6: 0.5
A7: j4 | B7: j5 | C7: t6 | D7: 0.5
A8: j4 | B8: j5 | C8: t7 | D8: 0.5
A9: j4 | B9: j5 | C9: t8 | D9: 0.04
A10: j4 | B10: j5 | C10: t9 | D10: 0.02
A11: j4 | B11: j5 | C11: t10 | D11: 0
A12: j4 | B12: j5 | C12: t11 | D12: 0
A13: j4 | B13: j5 | C13: t12 | D13: 0
... A241: j1 | B241: j4 | C241: t12 | D241: 0

Sheet NaturalGrowth
D1: cottonwood
A2: j4 | B2: j5 | C2: t1 | D2: 0
A3: j4 | B3: j5 | C3: t2 | D3: 0
A4: j4 | B4: j5 | C4: t3 | D4: 0
A5: j4 | B5: j5 | C5: t4 | D5: 0
A6: j4 | B6: j5 | C6: t5 | D6: 0
A7: j4 | B7: j5 | C7: t6 | D7: 0
A8: j4 | B8: j5 | C8: t7 | D8: 0
A9: j4 | B9: j5 | C9: t8 | D9: 0
A10: j4 | B10: j5 | C10: t9 | D10: 0
A11: j4 | B11: j5 | C11: t10 | D11: 0
A12: j4 | B12: j5 | C12: t11 | D12: 0
A13: j4 | B13: j5 | C13: t12 | D13: 0
... A325: j45 | B325: j32 | C325: t12 | D325: 0

Sheet Cmax
A1: j4 | B1: j5 | C1: =L1/1000000 -> 8.6592 | L1: 8659200
A2: j6 | B2: j5 | C2: =L2/1000000 -> 0.470914 | L2: 470914
A3: j5 | B3: j18 | C3: =L3/1000000 -> 11.079797 | L3: 11079797
A4: j18 | B4: j7 | C4: =L4/1000000 -> 1.049697 | L4: 1049697
A5: j7 | B5: j9 | C5: =L5/1000000 -> 0.683126 | L5: 683126
A6: j9 | B6: j12 | C6: =L6/1000000 -> 4.456809 | L6: 4456809
A7: j12 | B7: j14 | C7: =L7/1000000 -> 1.000458 | L7: 1000458
A8: j14 | B8: j17 | C8: =L8/1000000 -> 1.541125 | L8: 1541125
A9: j17 | B9: j20 | C9: =L9/1000000 -> 5.909368 | L9: 5909368
A10: j19 | B10: j20 | C10: =L10/1000000 -> 0.740186 | L10: 740186
A11: j20 | B11: j21 | C11: =L11/1000000 -> 2.224502 | L11: 2224502
A12: j31 | B12: j30 | C12: =L12/1000000 -> 0.477768 | L12: 477768
... A27: j26 | B27: j25 | C27: =L27/1000000 -> 0.883165 | L27: 883165

Sheet MaxVegCover
D1: cottonwood | M1: Floodplain (m2)
A2: j4 | B2: j5 | C2: t1 | D2: =M2/1000000 -> 8.6592 | M2: 8659200
A3: j4 | B3: j5 | C3: t2 | D3: =M3/1000000 -> 8.6592 | M3: 8659200
A4: j4 | B4: j5 | C4: t3 | D4: =M4/1000000 -> 8.6592 | M4: 8659200
A5: j4 | B5: j5 | C5: t4 | D5: =M5/1000000 -> 8.6592 | M5: 8659200
A6: j4 | B6: j5 | C6: t5 | D6: =M6/1000000 -> 8.6592 | M6: 8659200
A7: j4 | B7: j5 | C7: t6 | D7: =M7/1000000 -> 8.6592 | M7: 8659200
A8: j4 | B8: j5 | C8: t7 | D8: =M8/1000000 -> 8.6592 | M8: 8659200
A9: j4 | B9: j5 | C9: t8 | D9: =M9/1000000 -> 8.6592 | M9: 8659200
A10: j4 | B10: j5 | C10: t9 | D10: =M10/1000000 -> 8.6592 | M10: 8659200
A11: j4 | B11: j5 | C11: t10 | D11: =M11/1000000 -> 8.6592 | M11: 8659200
A12: j4 | B12: j5 | C12: t11 | D12: =M12/1000000 -> 8.6592 | M12: 8659200
A13: j4 | B13: j5 | C13: t12 | D13: =M13/1000000 -> 8.6592 | M13: 8659200
... A325: j26 | B325: j25 | C325: t12 | D325: =M325/1000000 -> 0.883165 | M325: 883165

Sheet SimLinks
A1: j1 | B1: j4 | C1: 1
A2: j6 | B2: j5 | C2: 1
A3: j31 | B3: j30 | C3: 1
A4: j34 | B4: j33 | C4: 1
A5: j19 | B5: j20 | C5: 1
A6: j20 | B6: j21 | C6: 1
A7: j21 | B7: j23 | C7: 1
A8: j32 | B8: j29 | C8: 1
A9: j7 | B9: j9 | C9: 1
A10: j22 | B10: j20 | C10: 1

Sheet Connect_Sim
B1: j1 | C1: j2 | D1: j3 | E1: j4 | F1: j5 | G1: j6 | H1: j7 | I1: j8 | J1: j9 | K1: j12 | L1: j13 | M1: j14 | N1: j15 | O1: j16 | P1: j17 | Q1: j18 | R1: j19 | S1: j20 | T1: j21 | U1: j22 | V1: j23 | W1: j24 | X1: j25 | Y1: j26 | Z1: j27 | AA1: j28 | AB1: j29 | AC1: j30 | AD1: j31 | AE1: j32 | AF1: j33 | AG1: j34 | AH1: j35 | AI1: j36 | AJ1: j37 | AK1: j38 | AL1: j39
A2: j1 | E2: 1
A3: j2 | D3: 1
A4: j3 | Q4: 1
A5: j4 | D5: 1 | F5: 1 | AL5: 1
A6: j5 | Q6: 1
A7: j6
A8: j7 | I8: 1 | J8: 1 | O8: 1
A9: j8 | J9: 1
A10: j9 | K10: 1
A11: j12 | L11: 1 | M11: 1 | N11: 1
A12: j13 | M12: 1
A13: j14
A14: j15 | M14: 1
A15: j16
A16: j17 | O16: 1 | S16: 1
A17: j18 | H17: 1
A18: j19
A19: j20 | T19: 1
A20: j21 | V20: 1
A21: j22 | S21: 1
A22: j23
A23: j24 | H23: 1
A24: j25 | W24: 1
A25: j26
A26: j27 | X26: 1
A27: j28 | W27: 1
A28: j29 | W28: 1 | AA28: 1
A29: j30 | X29: 1 | Z29: 1
A30: j31
A31: j32 | AB31: 1
A32: j33 | AE32: 1 | AK32: 1
A33: j34
A34: j35 | AE34: 1
A35: j36 | H35: 1
A36: j37
A37: j38 | AA37: 1 | AC37: 1
A38: j39 | Q38: 1

Sheet Qmax
C1: t1 | D1: t2 | E1: t3 | F1: t4 | G1: t5 | H1: t6 | I1: t7 | J1: t8 | K1: t9 | L1: t10 | M1: t11 | N1: t12
A2: j37 | B2: j1 | C2: =HeadFlow!B36+capacity!$B$1 -> 21.266482 | D2: =HeadFlow!C36+capacity!$B$1 -> 26.588725 | E2: =HeadFlow!D36+capacity!$B$1 -> 29.659233 | F2: =HeadFlow!E36+capacity!$B$1 -> 27.043714 | G2: =HeadFlow!F36+capacity!$B$1 -> 18.032911 | H2: =HeadFlow!G36+capacity!$B$1 -> 67.227595 | I2: =HeadFlow!H36+capacity!$B$1 -> 76.370406 | J2: =HeadFlow!I36+capacity!$B$1 -> 66.766579 | ... N2: =HeadFlow!M36+capacity!$B$1 -> 21.981016
A3: j1 | B3: j4 | C3: =$C$2 -> 21.266482 | D3: =$D$2 -> 26.588725 | E3: =$E$2 -> 29.659233 | F3: =$F$2 -> 27.043714 | G3: =$G$2 -> 18.032911 | H3: =$H$2 -> 67.227595 | I3: =$I$2 -> 76.370406 | J3: =$J$2 -> 66.766579 | K3: =$K$2 -> 31.87429 | L3: =$L$2 -> 16.034636 | M3: =$M$2 -> 21.262041 | N3: =$N$2 -> 21.981016
A4: j4 | B4: j5 | C4: =$C$2 -> 21.266482 | D4: =$D$2 -> 26.588725 | E4: =$E$2 -> 29.659233 | F4: =$F$2 -> 27.043714 | G4: =$G$2 -> 18.032911 | H4: =$H$2 -> 67.227595 | I4: =$I$2 -> 76.370406 | J4: =$J$2 -> 66.766579 | K4: =$K$2 -> 31.87429 | L4: =$L$2 -> 16.034636 | M4: =$M$2 -> 21.262041 | N4: =$N$2 -> 21.981016
A5: j6 | B5: j5 | C5: =HeadFlow!B7 -> 1.2510288 | D5: =HeadFlow!C7 -> 1.377621 | E5: =HeadFlow!D7 -> 2.3233392 | F5: =HeadFlow!E7 -> 6.0466392 | G5: =HeadFlow!F7 -> 27.098177 | H5: =HeadFlow!G7 -> 31.126788 | I5: =HeadFlow!H7 -> 8.3476386 | J5: =HeadFlow!I7 -> 4.0807368 | ... N5: =HeadFlow!M7 -> 1.2808152
A6: j5 | B6: j18 | C6: =C$2+C$5 -> 22.51751 | D6: =D$2+D$5 -> 27.966346 | E6: =E$2+E$5 -> 31.982572 | F6: =F$2+F$5 -> 33.090353 | G6: =G$2+G$5 -> 45.131088 | H6: =H$2+H$5 -> 98.354383 | I6: =I$2+I$5 -> 84.718044 | J6: =J$2+J$5 -> 70.847316 | ... N6: =N$2+N$5 -> 23.261831
A7: j2 | B7: j3 | C7: =C2 -> 21.266482 | D7: =D2 -> 26.588725 | E7: =E2 -> 29.659233 | F7: =F2 -> 27.043714 | G7: =G2 -> 18.032911 | H7: =H2 -> 67.227595 | I7: =I2 -> 76.370406 | J7: =J2 -> 66.766579 | ... N7: =N2 -> 21.981016
A8: j4 | B8: j3 | C8: =C2 -> 21.266482 | D8: =D2 -> 26.588725 | E8: =E2 -> 29.659233 | F8: =F2 -> 27.043714 | G8: =G2 -> 18.032911 | H8: =H2 -> 67.227595 | I8: =I2 -> 76.370406 | J8: =J2 -> 66.766579 | ... N8: =N2 -> 21.981016
A9: j3 | B9: j18 | C9: =C7 -> 21.266482 | D9: =D7 -> 26.588725 | E9: =E7 -> 29.659233 | F9: =F7 -> 27.043714 | G9: =G7 -> 18.032911 | H9: =H7 -> 67.227595 | I9: =I7 -> 76.370406 | J9: =J7 -> 66.766579 | ... N9: =N7 -> 21.981016
A10: j18 | B10: j7 | C10: =C6 -> 22.51751 | D10: =D6 -> 27.966346 | E10: =E6 -> 31.982572 | F10: =F6 -> 33.090353 | G10: =G6 -> 45.131088 | H10: =H6 -> 98.354383 | I10: =I6 -> 84.718044 | J10: =J6 -> 70.847316 | ... N10: =N6 -> 23.261831
